Workbook

Sheet BILAN
B3: Les Jeunes
C5: nb | D5: %age | K5: Nombre de missions proposées | P5: Nombre de missions distribuées | U5: Nombre de missions effectuées
B6: filles | C6: =COUNTIF(RECAP.JEUNES.2026!$L$6:L69,"f") -> 31 | D6: =(C6/RECAP.JEUNES.2026!L66)*100 -> 60.784314 | J6: Services | K6: Hiver | L6: Avril | M6: Été | N6: Automne | O6: TOTAL | P6: Hiver | Q6: Avril | R6: Été | S6: Automne | T6: TOTAL | U6: Hiver | V6: Avril | W6: Été | X6: Automne | Y6: TOTAL
B7: garçons | C7: =COUNTIF(RECAP.JEUNES.2026!$L$6:L70,"h") -> 20 | D7: =(C7/RECAP.JEUNES.2026!L66)*100 -> 39.215686 | J7: Enfance | L7: 4 | O7: =SUM(K7:N7) -> 4 | Q7: 4 | T7: =SUM(P7:S7) -> 4 | V7: 4 | Y7: =SUM(U7:X7) -> 4
J8: PRE | K8: 3 | L8: 6 | M8: 4 | O8: =SUM(K8:N8) -> 13 | P8: 3 | Q8: 4 | T8: =SUM(P8:S8) -> 7 | U8: 3 | V8: 4 | Y8: =SUM(U8:X8) -> 7
J9: Conservation et Valorisation du Pâtrimoine | K9: 7 | L9: 6 | M9: 78 | O9: =SUM(K9:N9) -> 91 | P9: 4 | Q9: 6 | T9: =SUM(P9:S9) -> 10 | U9: 4 | V9: 6 | Y9: =SUM(U9:X9) -> 10
J10: CTM | O10: =SUM(K10:N10) -> 0 | T10: =SUM(P10:S10) -> 0 | Y10: =SUM(U10:X10) -> 0
B11: Age | J11: Bibliothèque | K11: 1 | L11: 1 | M11: 6 | O11: =SUM(K11:N11) -> 8 | P11: 1 | Q11: 1 | T11: =SUM(P11:S11) -> 2 | U11: 1 | V11: 1 | Y11: =SUM(U11:X11) -> 2
B12: 14 ans | C12: =COUNTIF(RECAP.JEUNES.2026!$M$6:M65,"14 ans") -> 11 | D12: =(C12/RECAP.JEUNES.2026!$M$66) -> 0.21568627 | J12: Centre social - Atelier du 5 bis | M12: 8 | O12: =SUM(K12:N12) -> 8 | T12: =SUM(P12:S12) -> 0 | Y12: =SUM(U12:X12) -> 0
B13: 15 ans | C13: =COUNTIF(RECAP.JEUNES.2026!$M$6:M66,"15 ans") -> 11 | D13: =(C13/RECAP.JEUNES.2026!$M$66) -> 0.21568627 | J13: Ressources humaines | M13: 1 | O13: =SUM(K13:N13) -> 1 | T13: =SUM(P13:S13) -> 0 | Y13: =SUM(U13:X13) -> 0
B14: 16 ans | C14: =COUNTIF(RECAP.JEUNES.2026!$M$6:M67,"16 ans") -> 13 | D14: =(C14/RECAP.JEUNES.2026!$M$66) -> 0.25490196 | J14: Finances | M14: 5 | O14: =SUM(K14:N14) -> 5 | T14: =SUM(P14:S14) -> 0 | Y14: =SUM(U14:X14) -> 0
B15: 17 ans | C15: =COUNTIF(RECAP.JEUNES.2026!$M$6:M68,"17 ans") -> 11 | D15: =(C15/RECAP.JEUNES.2026!$M$66) -> 0.21568627 | J15: Vie Asso et sport | M15: 2 | O15: =SUM(K15:N15) -> 2
B16: 18 ans | C16: =COUNTIF(RECAP.JEUNES.2026!$M$6:M69,"18 ans") -> 5 | D16: =(C16/RECAP.JEUNES.2026!$M$66) -> 0.098039216 | J16: TOTAL | K16: =SUM(K7:K14) -> 11 | L16: =SUM(L7:L14) -> 17 | M16: =SUM(M7:M15) -> 104 | N16: =SUM(N7:N14) -> 0 | O16: =SUM(O7:O15) -> 132 | P16: =SUM(P7:P14) -> 8 | Q16: =SUM(Q7:Q14) -> 15 | R16: =SUM(R7:R14) -> 0 | S16: =SUM(S7:S14) -> 0 | T16: =SUM(T7:T15) -> 23 | U16: =SUM(U7:U14) -> 8 | V16: =SUM(V7:V14) -> 15 | W16: =SUM(W7:W14) -> 0 | X16: =SUM(X7:X14) -> 0 | Y16: =SUM(Y7:Y15) -> 23
C17: =SUM(C12:C16) -> 51 | D17: =SUM(D12:D16) -> 1
J19: Pourcentage de missions distribuées | K19: =T16/O16 -> 0.17424242
J20: Pourcentage de missions effectuées | K20: =Y16/T16 -> 1
C21: Prévisionnel | D21: Réel | E21: évolution
B22: nb de missions réalisées | C22: 110 | D22: =RECAP.JEUNES.2026!K66 -> 44
B23: nb de jeunes inscrits | D23: =RECAP.JEUNES.2026!L66 -> 51 | K23: Hiver | L23: Avril | M23: Été | N23: Automne | O23: TOTAL
B24: nb de jeunes missionés | C24: 40 | D24: =COUNTIFS(RECAP.JEUNES.2026!K6:K42,">0") -> 12 | J24: TOTAL des jeunes missionnés | K24: =RECAP.JEUNES.2026!G67 -> 5 | L24: =RECAP.JEUNES.2026!H67 -> 8 | M24: =RECAP.JEUNES.2026!I67 -> 7 | N24: =RECAP.JEUNES.2026!J67 -> 0 | O24: =SUM(K24:N24) -> 20
B25: financement total | C25: =C22*15 -> 1650 | D25: =HIVER.RECAPJ!H11+AVRIL.RECAPJ!I14+ETE.RECAPJ!D27+OCTOBRE.RECAPJ!F27 -> 735 | E25: =D25/C25 -> 0.44545455
B26: part CAF | C26: 550 | D26: =D22*5 -> 220 | E26: =D26/C26 -> 0.4
B27: part VILLE DINAN | C27: 1100 | D27: =D22*10 -> 440 | E27: =D27/C27 -> 0.4

Sheet RECAP.JEUNES.2026
B2: Récapitulatif Jeunes Argent de Poche 2026
G4: Nombre de missions effectuées
B5: Nom Prénom | C5: mail | D5: n° téléphone | E5: contact urgence | F5: Date de naissance | G5: Hiver | H5: Avril | I5: Été | J5: Automne | K5: TOTAL | L5: H/F | M5: âge | N5: année d'inscription
A6: 1 | B6: Rahain Noémie | C6: noemierahain@outlook.fr | D6: 06 66 69 62 56 | E6: 06 62 40 61 05 | F6: 39570 | K6: =SUM(G6:J6) -> 0 | L6: f | M6: =DATEDIF(F6,TODAY(),"Y")&" ans" -> 18 ans | N6: 2025
A7: 2 | B7: Diawara Ibrahim | C7: ibrahim12diawara@gmail.com | E7: 06 86 54 85 29 | F7: 39587 | K7: =SUM(G7:J7) -> 0 | L7: h | M7: =DATEDIF(F7,TODAY(),"Y")&" ans" -> 18 ans | N7: 2025
A8: 3 | B8: Plestan Mondet Julie | C8: plmondet.julie@gmail.com | D8: 07 69 04 86 78 | E8: 02 96 86 99 59 | F8: 39589 | G8: 1 | H8: 1 | K8: =SUM(G8:J8) -> 2 | L8: f | M8: =DATEDIF(F8,TODAY(),"Y")&" ans" -> 18 ans | N8: 2025
A9: 4 | B9: Picart Eloi | C9: eloipicart@gmail.com | D9: 07 68 14 22 84 | E9: 06 95 74 74 86 | F9: 39609 | K9: =SUM(G9:J9) -> 0 | L9: h | M9: =DATEDIF(F9,TODAY(),"Y")&" ans" -> 18 ans | N9: 2025
A10: 5 | B10: Robert-Tropree Perig | C10: perigroberttropree@gmail.com | D10: 07 86 09 44 12 | E10: 06 86 70 22 55 | F10: 39615 | K10: =SUM(G10:J10) -> 0 | L10: h | M10: =DATEDIF(F10,TODAY(),"Y")&" ans" -> 18 ans | N10: 2025
A11: 6 | B11: Bridenne Dylan | C11: shalemoussa@gmail.com | D11: 07 58 27 49 01 | E11: 06 80 17 26 42 | F11: 39678 | G11: 1 | K11: =SUM(G11:J11) -> 1 | L11: h | M11: =DATEDIF(F11,TODAY(),"Y")&" ans" -> 17 ans | N11: 2026
A12: 8 | B12: Bacar Zihayri | C12: zacharia.bacar@laposte.net | D12: 06 44 90 63 79 | E12: 07 69 28 75 59 | F12: 40399 | K12: =SUM(G12:J12) -> 0 | L12: h | M12: =DATEDIF(F12,TODAY(),"Y")&" ans" -> 15 ans | N12: 2025
A13: 9 | B13: Bertel-Cossé Heolig | C13: heolig.bertel@gmail.com | D13: 07 66 49 51 59 | E13: 07 82 03 58 86 | F13: 40715 | K13: =SUM(G13:J13) -> 0 | L13: h | M13: =DATEDIF(F13,TODAY(),"Y")&" ans" -> 15 ans | N13: 2026
A14: 10 | B14: Bertrand Maël | C14: jpierre.bertrand@laposte.net | D14: 07 76 18 28 60 | E14: 06 58 18 17 24 | F14: 39905 | H14: 1 | K14: =SUM(G14:J14) -> 1 | L14: h | M14: =DATEDIF(F14,TODAY(),"Y")&" ans" -> 17 ans | N14: 2026
A15: 11 | B15: Bertrand Noan | C15: jpierre.bertrand@laposte.net | E15: 07 82 52 39 05 | F15: 40731 | K15: =SUM(G15:J15) -> 0 | L15: h | M15: =DATEDIF(F15,TODAY(),"Y")&" ans" -> 14 ans | N15: 2026
A16: 12 | B16: Bourlet Kaïna | C16: saby-22@live.fr | D16: 06 79 63 91 13 | E16: 06 73 16 76 61 | F16: 40909 | I16: 4 | K16: =SUM(G16:J16) -> 4 | L16: f | M16: =DATEDIF(F16,TODAY(),"Y")&" ans" -> 14 ans | N16: 2026
A17: 13 | B17: Brazilier Savary Tristan | C17: braztristan@gmail.com | D17: 07 67 25 16 54 | E17: 06 75 75 97 86 | F17: 39952 | K17: =SUM(G17:J17) -> 0 | L17: h | M17: =DATEDIF(F17,TODAY(),"Y")&" ans" -> 17 ans | N17: 2025
A18: 14 | B18: Caron Caléane | C18: caleane.caron@gmail.com | D18: 07 88 02 14 26 | E18: 06 87 32 55 01 | F18: 39942 | K18: =SUM(G18:J18) -> 0 | L18: f | M18: =DATEDIF(F18,TODAY(),"Y")&" ans" -> 17 ans | N18: 2025
A19: 15 | B19: Caron Enora | C19: nanou.schaal@gmail.com | D19: 07 77 93 90 70 | E19: 06 87 32 55 01 | F19: 40851 | K19: =SUM(G19:J19) -> 0 | L19: f | M19: =DATEDIF(F19,TODAY(),"Y")&" ans" -> 14 ans | N19: 2026
A20: 16 | B20: Chameroy Leslé Louise | C20: louisechmy@gmail.com | D20: 07 81 18 05 34 | E20: 06 95 36 61 75 | F20: 40362 | G20: 3 | K20: =SUM(G20:J20) -> 3 | L20: f | M20: =DATEDIF(F20,TODAY(),"Y")&" ans" -> 15 ans | N20: 2025
A21: 17 | B21: Cochard Célia | C21: celiacochard2@gmail.com | D21: 07 64 02 71 84 | E21: 06 62 75 20 87 | F21: 40295 | G21: 2 | K21: =SUM(G21:J21) -> 2 | L21: f | M21: =DATEDIF(F21,TODAY(),"Y")&" ans" -> 16 ans | N21: 2025
A22: 18 | B22: Cormier Quitterie | C22: qcormier22@gmail.com | D22: 06 09 23 76 69 | E22: 06 24 48 27 45 | F22: 39857 | K22: =SUM(G22:J22) -> 0 | L22: f | M22: =DATEDIF(F22,TODAY(),"Y")&" ans" -> 17 ans | N22: 2025
A23: 19 | B23: Couchat Julyann | C23: cess.fa28@gmail.com | D23: 06 08 88 59 45 | E23: 06 35 12 57 10 | F23: 40325 | H23: 5 | K23: =SUM(G23:J23) -> 5 | L23: h | M23: =DATEDIF(F23,TODAY(),"Y")&" ans" -> 16 ans | N23: 2025
A24: 20 | B24: De Schrooder Mei-Lï | C24: cora_lee@live.fr | E24: 06 65 53 27 19 | F24: 40901 | K24: =SUM(G24:J24) -> 0 | L24: f | M24: =DATEDIF(F24,TODAY(),"Y")&" ans" -> 14 ans | N24: 2026
A25: 21 | B25: Delepine Jade | C25: jade.delep@outlook.fr | D25: 07 79 29 73 45 | E25: 06 99 11 41 33 | F25: 40163 | K25: =SUM(G25:J25) -> 0 | L25: f | M25: =DATEDIF(F25,TODAY(),"Y")&" ans" -> 16 ans | N25: 2025
A26: 22 | B26: Derien Angele | C26: oderet@gmail.com | D26: 06 68 60 40 49 | E26: 06 15 17 61 99 | F26: 40262 | K26: =SUM(G26:J26) -> 0 | L26: f | M26: =DATEDIF(F26,TODAY(),"Y")&" ans" -> 16 ans | N26: 2025
A27: 23 | B27: Dupont Celena | C27: mimi91230@msn.com | D27: 06 75 02 56 64 | E27: 06 28 47 63 31 | F27: 41031 | I27: 5 | K27: =SUM(G27:J27) -> 5 | L27: f | M27: =DATEDIF(F27,TODAY(),"Y")&" ans" -> 14 ans | N27: 2026
A28: 24 | B28: Fareed Bangura Alhaji | C28: bangurafareed4@gmail.com | E28: 06 03 31 30 04 | F28: 40504 | K28: =SUM(G28:J28) -> 0 | L28: h | M28: =DATEDIF(F28,TODAY(),"Y")&" ans" -> 15 ans | N28: 2026
A29: 25 | B29: Ferre Ben Ali Jimmy | D29: 06 99 36 43 56 | E29: 07 83 81 18 24 | F29: 40195 | K29: =SUM(G29:J29) -> 0 | L29: h | M29: =DATEDIF(F29,TODAY(),"Y")&" ans" -> 16 ans | N29: 2025
A30: 26 | B30: Gernigon Zélie | D30: 07 66 69 24 19 | E30: 06 81 16 42 85 | F30: 40218 | K30: =SUM(G30:J30) -> 0 | L30: f | M30: =DATEDIF(F30,TODAY(),"Y")&" ans" -> 16 ans | N30: 2025
A31: 27 | B31: Happe Charlotte | C31: happecharlotte5@gmail.com | D31: 06 79 93 73 79 | E31: 06 81 21 90 75 | F31: 40182 | K31: =SUM(G31:J31) -> 0 | L31: f | M31: =DATEDIF(F31,TODAY(),"Y")&" ans" -> 16 ans | N31: 2025
A32: 28 | B32: Lacoque Capucine | C32: clacoque@icloud.com | D32: 06 74 03 34 97 | E32: 06 88 48 86 17 | F32: 40165 | K32: =SUM(G32:J32) -> 0 | L32: f | M32: =DATEDIF(F32,TODAY(),"Y")&" ans" -> 16 ans | N32: 2026
A33: 29 | B33: Le Cadre Eloïse | C33: lecadre.eloise.fr@gmail.com | D33: 07 75 77 30 50 | E33: 06 13 99 05 87 | F33: 40609 | H33: 3 | K33: =SUM(G33:J33) -> 3 | L33: f | M33: =DATEDIF(F33,TODAY(),"Y")&" ans" -> 15 ans | N33: 2025
A34: 30 | B34: Le Couster Lison | C34: lecousterlison@gmail.com | D34: 07 81 14 38 07 | E34: 06 63 83 55 31 | F34: 40031 | K34: =SUM(G34:J34) -> 0 | L34: f | M34: =DATEDIF(F34,TODAY(),"Y")&" ans" -> 16 ans | N34: 2026
A35: 31 | B35: Le Pottier Lilian | C35: mazaninetti@yahoo.fr | D35: 07 60 56 71 79 | E35: 06 86 84 93 56 | F35: 40791 | K35: =SUM(G35:J35) -> 0 | L35: h | M35: =DATEDIF(F35,TODAY(),"Y")&" ans" -> 14 ans | N35: 2026
A36: 32 | B36: Lebret Keliah | D36: 07 44 75 66 55 | E36: 06 76 07 86 00 | F36: 40940 | H36: 1 | K36: =SUM(G36:J36) -> 1 | L36: f | M36: =DATEDIF(F36,TODAY(),"Y")&" ans" -> 14 ans | N36: 2026
A37: 33 | B37: Loquet Nathan | C37: zicannemaria@yahoo.fr | D37: 06 21 30 65 55 | E37: 06 51 75 86 59 | F37: 41055 | I37: 3 | K37: =SUM(G37:J37) -> 3 | L37: h | M37: =DATEDIF(F37,TODAY(),"Y")&" ans" -> 14 ans | N37: 2026
A38: 34 | B38: Menec Yuna | C38: yuyumen22@gmail.com | D38: 06 37 22 17 31 | E38: 06 75 36 90 51 | F38: 41054 | K38: =SUM(G38:J38) -> 0 | L38: f | M38: =DATEDIF(F38,TODAY(),"Y")&" ans" -> 14 ans | N38: 2026
A39: 35 | B39: Messager Rose | C39: rose.messager24@gmail.com | D39: 07 65 18 76 22 | E39: 06 50 70 38 58 | F39: 40292 | K39: =SUM(G39:J39) -> 0 | L39: f | M39: =DATEDIF(F39,TODAY(),"Y")&" ans" -> 16 ans | N39: 2025
A40: 36 | B40: Oillic Antonin | C40: oillic.celine@wanadoo.fr | D40: 06 71 45 39 23 | E40: 06 77 35 61 39 | F40: 40285 | K40: =SUM(G40:J40) -> 0 | L40: h | M40: =DATEDIF(F40,TODAY(),"Y")&" ans" -> 16 ans | N40: 2025
A41: 37 | B41: Paris Selma | C41: selmaparis999@gmail.com | D41: 07 82 74 76 80 | E41: 06 82 38 14 73 | F41: 40533 | K41: =SUM(G41:J41) -> 0 | L41: f | M41: =DATEDIF(F41,TODAY(),"Y")&" ans" -> 15 ans | N41: 2025
A42: 38 | B42: Péron Lili | C42: erwansophieperon@orange.fr | D42: 06 79 42 34 38 | E42: 06 18 01 78 80 | F42: 40571 | H42: 1 | K42: =SUM(G42:J42) -> 1 | L42: f | M42: =DATEDIF(F42,TODAY(),"Y")&" ans" -> 15 ans | N42: 2025
...

Sheet HIVER.RECAPJ
B1: Jeunes missionnés Hiver 2026
C3: n° téléphone | D3: contact urgence | E3: Nbre missions Semaine 1 | F3: Nbre missions Semaine 2 | G3: Nbre de missions Total | H3: A payer | I3: Attestations reçues ?
A4: 1 | B4: Célia Cochard | C4: 07.64.02.71.84 | D4: 06.62.75.20.87 | E4: 2 | G4: =E4+F4 -> 2 | H4: =15*G4 -> 30 | I4: ok
A5: 2 | B5: Plestan Mondet Julie | C5: 07.69.04.86.78 | D5: 02.96.86.99.59 | F5: 1 | G5: =E5+F5 -> 1 | H5: =15*G5 -> 15 | I5: ok
A6: 3 | B6: Louise Chameroy | C6: 07.81.18.05.34 | E6: 2 | F6: 1 | G6: =E6+F6 -> 3 | H6: =15*G6 -> 45 | I6: ok
A7: 4 | B7: Dylan Bridenne | C7: 07.58.27.49.01 | D7: 06.80.17.26.42 | F7: 1 | G7: =E7+F7 -> 1 | H7: =15*G7 -> 15 | I7: ok
A8: 5 | B8: Pol Robert | C8: 07.86.49.21.65 | D8: 07.86.49.21.65 | E8: 1 | G8: =E8+F8 -> 1 | H8: =15*G8 -> 15 | I8: ok
A9: 6 | G9: =E9+F9 -> 0 | H9: =15*G9 -> 0
A10: 7 | G10: =E10+F10 -> 0 | H10: =15*G10 -> 0
B11: =COUNTA(B4:B10) -> 5 | E11: =SUM(E4:E10) -> 5 | F11: =SUM(F4:F10) -> 3 | G11: =SUM(G4:G10) -> 8 | H11: =SUM(H4:H10) -> 120

Sheet HIVER.MISSION
A1: Hiver 2025 | D1: Missions | K1: Missions 2 | O1: Missions 3 | S1: Missions 4 | W1: Missions 5
A2: Jour | B2: date | C2: horaires | D2: Service | E2: Mission | F2: lieu de RDV | G2: Heure | H2: Référent | I2: Contact | J2: Jeune missionné | K2: Service | L2: Mission | M2: Heure | N2: Candidature | O2: Service | P2: Mission | Q2: Heure | R2: Candidature | S2: Service | T2: Mission | U2: Heure | V2: candidature | W2: Service | X2: Mission | Y2: heure | Z2: candidature
A3: Lundi | B3: 46069 | C3: Matin
C4: A-M | D4: PRE | F4: Atelier 5BIS | G4: 13h45-16h45 | H4: Audrey-Louise Hanchard | I4: 06.67.33.92.73 | J4: Célia Cochard
A5: Mardi | B5: 46070 | C5: Matin | D5: BM | E5: inventaire rayon livres | F5: BM | G5: 9h-12h | H5: Sophie Peron | I5: 02 96 39 05 02 | J5: Louise Chameroy
C6: A-M | D6: PRE | F6: Atelier 5BIS | G6: 13h45-16h45 | H6: Audrey-Louise Hanchard | I6: 06.67.33.92.73 | J6: Célia Cochard
A7: Mercredi | B7: 46071 | C7: Matin
C8: A-M | D8: PRE | F8: Atelier 5BIS | G8: 13h45-16h45 | H8: Audrey-Louise Hanchard | I8: 06.67.33.92.73 | J8: Louise Chameroy
A9: Jeudi | B9: 46072 | C9: Matin | D9: Atelier du 5 bis | F9: Atelier du 5 bis | G9: 9h-12h | H9: Nathalie | J9: Liz Piriou ANNULE MALADE
C10: A-M
A11: Vendredi | B11: 46073 | C11: Matin
C12: A-M
A13: Lundi | B13: 46076 | C13: Matin
C14: A-M
A15: Mardi | B15: 46077 | C15: Matin
C16: A-M
A17: Mercredi | B17: 46078 | C17: Matin
C18: A-M
A19: Jeudi | B19: 46079 | C19: Matin
C20: A-M
A21: Vendredi | B21: 46080 | C21: Matin
C22: A-M
A24: Hiver 2025 | D24: Missions | L24: PRE | M24: 9
A25: Jour | C25: date | D25: Service | E25: Mission | F25: lieu de RDV | G25: Heure | H25: Référent | I25: Contact | J25: Jeune missionné | L25: CTM Léhon | M25: 2
A26: Lundi | B26: 46069 | C26: Matin | L26: Bibliothèque | M26: 2
C27: A-M | L27: Vie Asso | M27: 1
A28: Mardi | B28: 46070 | C28: Matin | D28: Patrimoine | E28: retranscrire le sommaire des pays de Dinan | F28: mairie délégué Léhon | G28: 9h-12h | H28: Thibault Bruneau | I28: 02 96 87 40 49 / 07 60 55 16 07 | J28: Liz Piriou changement avec mercredi | L28: 5Bis | M28: 1
C29: A-M | D29: Patrimoine | E29: retranscrire le sommaire des pays de Dinan | F29: mairie délégué Léhon | G29: 14h-17h | H29: Thibault Bruneau | I29: 02 96 87 40 49 / 07 60 55 16 07 | J29: Pol ROBERT | L29: Patrimoine | M29: 3
A30: Mercredi | B30: 46071 | C30: Matin | D30: Patrimoine | E30: retranscrire le sommaire des pays de Dinan | F30: mairie délégué Léhon | G30: 9h-12h | H30: Emeline | I30: 02 96 87 40 49 / 07 60 55 16 07 | J30: Liz Piriou changement avec jeudi | L30: TOTAL | M30: =SUM(M24:M29) -> 18
C31: A-M
A32: Jeudi | B32: 46072 | C32: Matin
C33: A-M
A34: Vendredi | B34: 46073 | C34: Matin
C35: A-M
A36: Lundi | B36: 46076 | C36: Matin
C37: A-M
A38: Mardi | B38: 46077 | C38: Matin
C39: A-M
A40: Mercredi | B40: 46078 | C40: Matin | D40: Patrimoine | E40: retranscrire le sommaire des pays de Dinan | F40: mairie délégué Léhon | G40: 9h-12h | H40: Thibault Bruneau | I40: 02 96 87 40 49 / 07 60 55 16 07
C41: A-M | D41: Patrimoine | E41: retranscrire le sommaire des pays de Dinan | F41: mairie délégué Léhon | G41: 14h-17h | H41: Thibault Bruneau | I41: 02 96 87 40 49 / 07 60 55 16 07 | J41: Louise Chameroy
...

Sheet AVRIL.MISSIONS
A1: Missions Argent de poche
A3: Avril | B3: Jour | C3: Lundi | E3: Mardi | G3: Mercredi | I3: Jeudi | K3: Vendredi | M3: Lundi | O3: Mardi | Q3: Mercredi | S3: Jeudi | U3: Vendredi
B4: Date | C4: 46125 | E4: 46126 | G4: 46127 | I4: 46128 | K4: 46129 | M4: 46132 | O4: 46133 | Q4: 46134 | S4: 46135 | U4: 46136
B5: Horaires | C5: Matin | D5: A-M | E5: Matin | F5: A-M | G5: Matin | H5: A-M | I5: Matin | J5: A-M | K5: Matin | L5: A-M | M5: Matin | N5: A-M | O5: Matin | P5: A-M | Q5: Matin | R5: A-M | S5: Matin | T5: A-M | U5: Matin | V5: A-M
A6: Missions 1/2 | B6: Heure | C6: 9h30-12h30 | D6: 14h-17h | E6: 9h30-12h30 | G6: 9h30-12h30 | H6: 14h-17h | K6: 9h-12h | L6: 14h-17h | N6: 14h-17h | R6: 14h-17h | U6: 9h-12h | V6: 14h-17h
B7: Missions | C7: Ranger la bibliothèque de l'école et plastifier des livres | D7: préparation des ateliers jeune public / enquête de satisfaction | E7: Ranger la bibliothèque de l'école et plastifier des livres | G7: Ranger la bibliothèque de l'école et plastifier des livres | H7: préparation des ateliers jeune public / enquête de satisfaction | K7: Trier des jeux de société | L7: préparation des ateliers jeune public / enquête de satisfaction | N7: préparation des ateliers jeune public / enquête de satisfaction | R7: préparation des ateliers jeune public / enquête de satisfaction | U7: Traitement des ouvrages retirés des collections | V7: préparation des ateliers jeune public / enquête de satisfaction
B8: lieu de RDV | C8: Ecole de la Ruche | D8: Château de Dinan | E8: Ecole de la Ruche | G8: Ecole de la Ruche | H8: Château de Dinan | K8: Ecole des Fontaines | L8: Château de Dinan | N8: Château de Dinan | R8: Château de Dinan | U8: Bibliothèque | V8: Château de Dinan
B9: Référent | C9: Audrey-Louise | D9: Solène Gandanger | E9: Audrey-Louise | G9: Audrey-Louise | H9: Alice Marec | K9: Scarlett | L9: Alice Marec | N9: Solène Gandanger | R9: Alice Marec | U9: Blandine / Ouriel | V9: Zoé Hamelin
B10: Contact | C10: 06 67 33 92 73 | D10: 07 60 55 11 53 | E10: 06 67 33 92 73 | G10: 06 67 33 92 73 | H10: 06 58 26 59 06 | K10: 06 98 11 85 24 | L10: 06 58 26 59 06 | N10: 07 60 55 11 53 | R10: 06 58 26 59 06 | U10: 02 96 39 51 16 | V10: 07 60 55 11 53
B11: Jeune missionné | C11: 2 jeunes : - COUCHAT Julyann | D11: 1 jeune : - Eloise Le Cadre | E11: 2 jeunes : - COUCHAT Julyann | G11: 2 jeunes : - Eloise Le Cadre - Liz Piriou | H11: 1 jeune : - COUCHAT Julyann | K11: 2 jeunes : - Lili Peron - Maël Bertrand | L11: 1 jeune : - Pol Robert | N11: 1 jeune : - COUCHAT Julyann | R11: 1 jeune : - COUCHAT Julyann | U11: 1 jeune : - Liz Piriou | V11: 1 jeune : Julie Plestan Mondet
B12: Service | C12: PRE | D12: CVPatri | E12: PRE | G12: PRE | H12: CVPatri | K12: Enfance | L12: CVPatri | N12: CVPatri | R12: CVPatri | U12: Bibliothèque | V12: CVPatri
A13: Missions 2/2 | B13: Heure | E13: 9h-12h
B14: Missions | E14: Trier des jeux de société
B15: lieu de RDV | E15: Ecole des Fontaines
B16: Référent | E16: Scarlett
B17: Contact | E17: 06 98 11 85 24
B18: Jeune missionné | E18: 2 jeunes : -Keliah Le Bret - Eloise Le Cadre
B19: Service | E19: Enfance

Sheet AVRIL.RECAPJ
B1: Jeunes missionnés en AVRIL 2026
C3: n° téléphone | D3: contact urgence | E3: Date de naissance | F3: Nbre missions Semaine 1 | G3: Nbre missions Semaine 2 | H3: Nbre de missions Total | I3: A payer | J3: Attestations reçues ? | K3: Envoyé aux Finances ?
B4: Robert Pol | C4: 07 86 49 21 65 | D4: 07 86 49 21 65 | E4: 40950 | F4: 1 | H4: =SUM(F4:G4) -> 1 | I4: =H4*15 -> 15 | J4: 1 | K4: ok
B5: Bertrand Maël | C5: 07 76 18 28 60 | D5: 06 58 18 17 24 | E5: 39905 | F5: 1 | H5: =SUM(F5:G5) -> 1 | I5: =H5*15 -> 15 | J5: 1 | K5: ok
B6: Peron Lili | C6: 06 79 42 34 38 | D6: 06 18 01 78 80 | E6: 40571 | F6: 1 | H6: =SUM(F6:G6) -> 1 | I6: =H6*15 -> 15 | J6: 1 | K6: ok
B7: Le Cadre Eloïse | C7: 07 75 77 30 50 | D7: 06 13 99 05 87 | E7: 40609 | F7: 3 | H7: =SUM(F7:G7) -> 3 | I7: =H7*15 -> 45 | J7: 3 | K7: ok
B8: Couchat Julyann | C8: 06 08 88 59 45 | D8: 06 35 12 57 10 | E8: 40325 | F8: 3 | G8: 2 | H8: =SUM(F8:G8) -> 5 | I8: =H8*15 -> 75 | J8: 5 | K8: ok
B9: Piriou Liz | C9: 07 68 14 22 84 | D9: 06 95 74 74 86 | E9: 39609 | F9: 1 | G9: 1 | H9: =SUM(F9:G9) -> 2 | I9: =H9*15 -> 30 | J9: 2 | K9: ok
B10: Lebret Keliah | C10: 07 44 75 66 55 | D10: 06 76 07 86 00 | E10: 40940 | F10: 1 | H10: =SUM(F10:G10) -> 1 | I10: =H10*15 -> 15 | J10: 1 | K10: ok
B11: Plestan Mondet Julie | C11: 07 69 04 86 78 | D11: 02 96 86 99 59 | E11: 39589 | G11: 1 | H11: =SUM(F11:G11) -> 1 | I11: =H11*15 -> 15 | J11: 1 | K11: ok
H12: =SUM(F12:G12) -> 0 | I12: =H12*15 -> 0
H13: =SUM(F13:G13) -> 0 | I13: =H13*15 -> 0
B14: =COUNTA(B4:B13) -> 8 | F14: =SUM(F4:F13) -> 11 | G14: =SUM(G4:G13) -> 4 | H14: =SUM(H4:H13) -> 15 | I14: =SUM(I4:I12) -> 225

Sheet ETE.MISSION
A1: Missions Argent de poche
A3: Juillet | B3: Date | C3: 46209 | E3: 46210 | G3: 46211 | I3: 46212 | K3: 46213 | N3: 46207
B4: Horaires | C4: Matin | D4: A-M | E4: Matin | F4: A-M | G4: Matin | H4: A-M | I4: Matin | J4: A-M | K4: Matin | L4: A-M | N4: Matin | O4: A-M
A5: Missions 1/3 | B5: Heure | C5: 11h30-14h30 | D5: 14h30-17h30 | E5: 11h30-14h30 | F5: 14h30-17h30 | G5: 11h30-14h30 | H5: 14h30-17h30 | I5: 11h30-14h30 | J5: 14h30-17h30 | K5: 11h30-14h30 | L5: 14h30-17h30 | N5: 13h-16h | O5: 16h-19h
B6: Missions | C6: enquête satisfaction auprès des visiteurs du château + aide à la préparation des ateliers pédagogiques | D6: enquête satisfaction auprès des visiteurs du château + aide à la préparation des ateliers pédagogiques | E6: enquête satisfaction auprès des visiteurs du château + aide à la préparation des ateliers pédagogiques | F6: enquête satisfaction auprès des visiteurs du château + aide à la préparation des ateliers pédagogiques | G6: enquête satisfaction auprès des visiteurs du château + aide à la préparation des ateliers pédagogiques | H6: enquête satisfaction auprès des visiteurs du château + aide à la préparation des ateliers pédagogiques | I6: enquête satisfaction auprès des visiteurs du château + aide à la préparation des ateliers pédagogiques | J6: enquête satisfaction auprès des visiteurs du château + aide à la préparation des ateliers pédagogiques | K6: enquête satisfaction auprès des visiteurs du château + aide à la préparation des ateliers pédagogiques | L6: enquête satisfaction auprès des visiteurs du château + aide à la préparation des ateliers pédagogiques | N6: 50 ans Centre social : aide à l'installation et animation de stand | O6: 50 ans Centre social : animation de stand et aide à la désinstallation
B7: lieu de RDV | C7: Château de Dinan | D7: Château de Dinan | E7: Château de Dinan | F7: Château de Dinan | G7: Château de Dinan | H7: Château de Dinan | I7: Château de Dinan | J7: Château de Dinan | K7: Château de Dinan | L7: Château de Dinan | N7: Atelier du 5 bis | O7: Atelier du 5 bis
B8: Référent | C8: Naïla Jehan | D8: Naïla Jehan | E8: Naïla Jehan | F8: Naïla Jehan | G8: Naïla Jehan | H8: Naïla Jehan | I8: Naïla Jehan | J8: Naïla Jehan | K8: Naïla Jehan | L8: Naïla Jehan | N8: Noémie Gamblin | O8: Noémie Gamblin
B9: Contact | C9: 02 96 39 45 20 | D9: 02 96 39 45 20 | E9: 02 96 39 45 20 | F9: 02 96 39 45 20 | G9: 02 96 39 45 20 | H9: 02 96 39 45 20 | I9: 02 96 39 45 20 | J9: 02 96 39 45 20 | K9: 02 96 39 45 20 | L9: 02 96 39 45 20 | N9: 02 96 39 38 21 | O9: 02 96 39 38 21
B10: nombre de jeunes missionnés | C10: 1. Nathan Loquet | D10: 1 | E10: 1 | F10: 1 | G10: 1 | H10: 1 - Dupont Céléna | I10: 1 | J10: 1. Alexia Salliou | K10: 1. Noam Brindejonc | L10: 1. Liz Smith Lefebvre | N10: 2. Brindejonc Noam Nathanb Loquet | O10: 2.
B11: Service | C11: Conservation et Valorisation des Patirmoines | D11: Conservation et Valorisation des Patirmoines | E11: Conservation et Valorisation des Patirmoines | F11: Conservation et Valorisation des Patirmoines | G11: Conservation et Valorisation des Patirmoines | H11: Conservation et Valorisation des Patirmoines | I11: Conservation et Valorisation des Patirmoines | J11: Conservation et Valorisation des Patirmoines | K11: Conservation et Valorisation des Patirmoines | L11: Conservation et Valorisation des Patirmoines | N11: Atelier du 5 bis | O11: Atelier du 5 bis
A12: Missions 2/3 | B12: Heure | C12: 9h30 - 12h30 | E12: 9h30 - 12h30 | F12: 14h-17h | G12: 9H à 12H | I12: 9h-12h | J12: 14h-17h | K12: 9h-12h
B13: Missions | C13: Rangement bibliothèque, Couvrir des Livres | E13: Plastifier, découper jeux club coup de pouce | F13: registres des impayés - siasies de données excel | G13: Classement, saisie de données, Impression | I13: registres des impayés - siasies de données excel | J13: registres des impayés - siasies de données excel | K13: Tri des revues pour le désherbage et la braderie
B14: lieu de RDV | C14: École de la Ruche | E14: École de la Ruche | F14: Service finances 2e étage 5 rue Gambetta | G14: Service RH 2ème étage du 5 rue Gambetta, bureau de C. Doualan disponible | I14: Service finances 2e étage 5 rue Gambetta | J14: Service finances 2e étage 5 rue Gambetta | K14: Bibliothèque (entrée du personnel)
B15: Référent | C15: Audrey-louise | E15: Audrey-louise | F15: Nelly Plessis | G15: Bénédicte MEYER | I15: Nelly Plessis | J15: Nelly Plessis | K15: Sophie Péron
B16: Contact | C16: 06 67 33 92 73 | E16: 06 67 33 92 73 | F16: 07 64 45 33 86 | G16: 02 96 87 40 56 | I16: 07 64 45 33 86 | J16: 07 64 45 33 86
B17: nombre de jeunes missionnés | C17: 2. Robert-Tropree Marig | E17: 2. Dupont Céléna Robert-Tropree Marig | F17: 1. Noam Brindejonc | G17: 1. Nathan Loquet | I17: 1. Dupont Céléna | J17: 1 | K17: 1. Dupont Céléna
B18: Service | C18: Enfance / Éducation | E18: Enfance / Éducation | F18: Finances | G18: RH | I18: Finances | J18: Finances | K18: Bibliothèque / Culture
A19: Missions 3/3 | B19: Heure | E19: 9h-12h
B20: Missions | E20: Rangement / désherbage
B21: lieu de RDV | E21: Bibliothèque
B22: Référent | E22: Maï Goupil
B23: Contact | E23: 02 96 39 22 43
B24: nombre de jeunes missionnés | E24: 1. Kaïna Bourlet
B25: Service | E25: Bibliothèque
A30: Juillet | B30: Date | C30: 46216 | E30: 46217 | G30: 46218 | I30: 46219 | K30: 46220
B31: Horaires | C31: Matin | D31: A-M | E31: Matin | F31: A-M | G31: Matin | H31: A-M | I31: Matin | J31: A-M | K31: Matin | L31: A-M
A32: Missions 1/2 | B32: Heure | C32: 11h30-14h30 | D32: 14h30-17h30 | E32: FERIE | G32: 11h30-14h30 | H32: 14h30-17h30 | I32: 11h30-14h30 | J32: 14h30-17h30 | K32: 11h30-14h30 | L32: 14h30-17h30
B33: Missions | C33: enquête satisfaction auprès des visiteurs du château + aide à la préparation des ateliers pédagogiques | D33: enquête satisfaction auprès des visiteurs du château + aide à la préparation des ateliers pédagogiques | G33: enquête satisfaction auprès des visiteurs du château + aide à la préparation des ateliers pédagogiques | H33: enquête satisfaction auprès des visiteurs du château + aide à la préparation des ateliers pédagogiques | I33: enquête satisfaction auprès des visiteurs du château + aide à la préparation des ateliers pédagogiques | J33: enquête satisfaction auprès des visiteurs du château + aide à la préparation des ateliers pédagogiques | K33: enquête satisfaction auprès des visiteurs du château + aide à la préparation des ateliers pédagogiques | L33: enquête satisfaction auprès des visiteurs du château + aide à la préparation des ateliers pédagogiques
B34: lieu de RDV | C34: Château de Dinan | D34: Château de Dinan | G34: Château de Dinan | H34: Château de Dinan | I34: Château de Dinan | J34: Château de Dinan | K34: Château de Dinan | L34: Château de Dinan
B35: Référent | C35: Zoé Hamelin | D35: Zoé Hamelin | G35: Naïla Jehan | H35: Naïla Jehan | I35: Naïla Jehan | J35: Naïla Jehan | K35: Zoé Hamelin | L35: Zoé Hamelin
B36: Contact | C36: 02 96 39 45 20 | D36: 02 96 39 45 20 | G36: 02 96 39 45 20 | H36: 02 96 39 45 20 | I36: 02 96 39 45 20 | J36: 02 96 39 45 20 | K36: 02 96 39 45 20 | L36: 02 96 39 45 20
B37: nombre de jeunes missionnés | C37: 1 | D37: 1 | G37: 1. Dupont Céléna | H37: 1. Alexia Salliou | I37: 1 | J37: 1. Kaïna Bourlet | K37: 1 | L37: 1. Kaïna Bourlet
B38: Service | C38: Conservation et Valorisation des Patirmoines | D38: Conservation et Valorisation des Patirmoines | G38: Conservation et Valorisation des Patirmoines | H38: Conservation et Valorisation des Patirmoines | I38: Conservation et Valorisation des Patirmoines | J38: Conservation et Valorisation des Patirmoines | K38: Conservation et Valorisation des Patirmoines | L38: Conservation et Valorisation des Patirmoines
A39: Missions 2/2 | B39: Heure | K39: 9h-12h
B40: Missions | K40: Traitement des revues pour la braderie et fabrication d'enveloppes pour la grainothèque
B41: lieu de RDV | K41: Bibliothèque (entrée du personnel)
B42: Référent | K42: Sophie Péron
B43: Contact
B44: nombre de jeunes missionnés | K44: 1. Alexia Salliou
B45: Service | K45: Bibliothèque / Culture
...

Sheet ETE.RECAPJ
B2: Jeunes missionnés - été 2026
C4: Nbre de missions Total | D4: à payer | E4: Attestations reçues ? | F4: envoyé aux Finances ?
B5: Bourlet Kaïna | C5: 4 | D5: =C5*15 -> 60
B6: Dupont Celena | C6: 5 | D6: =C6*15 -> 75
B7: Loquet Nathan | C7: 3 | D7: =C7*15 -> 45
B8: Robert-Tropree Marig | C8: 2 | D8: =C8*15 -> 30
B9: Salliou Alexia | C9: 5 | D9: =C9*15 -> 75
B10: Smith Lefebvre Liz | C10: 2 | D10: =C10*15 -> 30
B11: Brindejonc-Regnault Noam | C11: 5 | D11: =C11*15 -> 75
D12: =C12*15 -> 0
D13: =C13*15 -> 0
D14: =C14*15 -> 0
D15: =C15*15 -> 0
D16: =C16*15 -> 0
D17: =C17*15 -> 0
D18: =C18*15 -> 0
D19: =C19*15 -> 0
D20: =C20*15 -> 0
D21: =C21*15 -> 0
D22: =C22*15 -> 0
D23: =C23*15 -> 0
... D26: =C26*15 -> 0
C27: =SUM(C5:C26) -> 26 | D27: =SUM(D5:D20) -> 390

Sheet OCTOBRE.MISSION
A1: Missions Argent de poche
A3: octobre | B3: Date | C3: 46125 | E3: 46126 | G3: 46127 | I3: 46128 | K3: 46129 | M3: 46132 | O3: 46133 | Q3: 46134 | S3: 46135 | U3: 46136
B4: Horaires | C4: Matin | D4: A-M | E4: Matin | F4: A-M | G4: Matin | H4: A-M | I4: Matin | J4: A-M | K4: Matin | L4: A-M | M4: Matin | N4: A-M | O4: Matin | P4: A-M | Q4: Matin | R4: A-M | S4: Matin | T4: A-M | U4: Matin | V4: A-M
A5: Missions 1/2 | B5: Heure
B6: Missions
B7: lieu de RDV
B8: Référent
B9: Contact
B10: Jeune missionné
B11: Service
A12: Missions 2/2 | B12: Heure
B13: Missions
B14: lieu de RDV
B15: Référent
B16: Contact
B17: Jeune missionné
B18: Service

Sheet OCTOBRE.RECAPJ
B2: Jeunes missionnés en ETE 2025
C4: Nbre missions Juillet | D4: Nbre missions Aout | E4: Nbre de missions Total | F4: à payer | G4: Attestations reçues ? | H4: envoyé aux Finances ?
F5: =E5*15 -> 0
F6: =E6*15 -> 0
F7: =E7*15 -> 0
F8: =E8*15 -> 0
F9: =E9*15 -> 0
F10: =E10*15 -> 0
F11: =E11*15 -> 0
F12: =E12*15 -> 0
F13: =E13*15 -> 0
F14: =E14*15 -> 0
F15: =E15*15 -> 0
F16: =E16*15 -> 0
... F26: =E26*15 -> 0
C27: =SUM(C5:C26) -> 0 | D27: =SUM(D5:D26) -> 0 | E27: =SUM(E5:E26) -> 0 | F27: =SUM(F5:F20) -> 0
